[2023-11-30T01:19:22.139+0200] {taskinstance.py:1159} INFO - Dependencies all met for dep_context=non-requeueable deps ti=<TaskInstance: lviv_weather.create_table_sqlite manual__2023-11-29T23:19:13.724547+00:00 [queued]>
[2023-11-30T01:19:22.152+0200] {taskinstance.py:1159} INFO - Dependencies all met for dep_context=requeueable deps ti=<TaskInstance: lviv_weather.create_table_sqlite manual__2023-11-29T23:19:13.724547+00:00 [queued]>
[2023-11-30T01:19:22.153+0200] {taskinstance.py:1361} INFO - Starting attempt 1 of 1
[2023-11-30T01:19:22.208+0200] {taskinstance.py:1382} INFO - Executing <Task(SqliteOperator): create_table_sqlite> on 2023-11-29 23:19:13.724547+00:00
[2023-11-30T01:19:22.213+0200] {standard_task_runner.py:57} INFO - Started process 142311 to run task
[2023-11-30T01:19:22.227+0200] {standard_task_runner.py:84} INFO - Running: ['airflow', 'tasks', 'run', 'lviv_weather', 'create_table_sqlite', 'manual__2023-11-29T23:19:13.724547+00:00', '--job-id', '16', '--raw', '--subdir', 'DAGS_FOLDER/lviv_weather.py', '--cfg-path', '/tmp/tmpqcqlquee']
[2023-11-30T01:19:22.229+0200] {standard_task_runner.py:85} INFO - Job 16: Subtask create_table_sqlite
[2023-11-30T01:19:22.443+0200] {task_command.py:416} INFO - Running <TaskInstance: lviv_weather.create_table_sqlite manual__2023-11-29T23:19:13.724547+00:00 [running]> on host yurabd.
[2023-11-30T01:19:22.907+0200] {taskinstance.py:1662} INFO - Exporting env vars: AIRFLOW_CTX_DAG_OWNER='airflow' AIRFLOW_CTX_DAG_ID='lviv_weather' AIRFLOW_CTX_TASK_ID='create_table_sqlite' AIRFLOW_CTX_EXECUTION_DATE='2023-11-29T23:19:13.724547+00:00' AIRFLOW_CTX_TRY_NUMBER='1' AIRFLOW_CTX_DAG_RUN_ID='manual__2023-11-29T23:19:13.724547+00:00'
[2023-11-30T01:19:22.908+0200] {sql.py:274} INFO - Executing: 
        CREATE TABLE IF NOT EXISTS measures
        (
        timestamp TIMESTAMP,
        date TEXT,
        temp FLOAT
        );
[2023-11-30T01:19:22.964+0200] {taskinstance.py:1937} ERROR - Task failed with exception
Traceback (most recent call last):
  File "/mnt/f/UCU/BatchProc/lab1/venv/lib/python3.10/site-packages/airflow/providers/common/sql/operators/sql.py", line 275, in execute
    hook = self.get_db_hook()
  File "/mnt/f/UCU/BatchProc/lab1/venv/lib/python3.10/site-packages/airflow/providers/common/sql/operators/sql.py", line 186, in get_db_hook
    return self._hook
  File "/usr/lib/python3.10/functools.py", line 981, in __get__
    val = self.func(instance)
  File "/mnt/f/UCU/BatchProc/lab1/venv/lib/python3.10/site-packages/airflow/providers/common/sql/operators/sql.py", line 148, in _hook
    conn = BaseHook.get_connection(conn_id)
  File "/mnt/f/UCU/BatchProc/lab1/venv/lib/python3.10/site-packages/airflow/hooks/base.py", line 72, in get_connection
    conn = Connection.get_connection_from_secrets(conn_id)
  File "/mnt/f/UCU/BatchProc/lab1/venv/lib/python3.10/site-packages/airflow/models/connection.py", line 477, in get_connection_from_secrets
    raise AirflowNotFoundException(f"The conn_id `{conn_id}` isn't defined")
airflow.exceptions.AirflowNotFoundException: The conn_id `airflow_conn` isn't defined
[2023-11-30T01:19:22.985+0200] {taskinstance.py:1400} INFO - Marking task as FAILED. dag_id=lviv_weather, task_id=create_table_sqlite, execution_date=20231129T231913, start_date=20231129T231922, end_date=20231129T231922
[2023-11-30T01:19:23.015+0200] {standard_task_runner.py:104} ERROR - Failed to execute job 16 for task create_table_sqlite (The conn_id `airflow_conn` isn't defined; 142311)
[2023-11-30T01:19:23.042+0200] {local_task_job_runner.py:228} INFO - Task exited with return code 1
[2023-11-30T01:19:23.091+0200] {taskinstance.py:2778} INFO - 0 downstream tasks scheduled from follow-on schedule check
