[2023-11-30T02:00:13.994+0200] {taskinstance.py:1159} INFO - Dependencies all met for dep_context=non-requeueable deps ti=<TaskInstance: lviv_weather.create_table_postgres scheduled__2023-11-29T00:00:00+00:00 [queued]>
[2023-11-30T02:00:14.001+0200] {taskinstance.py:1159} INFO - Dependencies all met for dep_context=requeueable deps ti=<TaskInstance: lviv_weather.create_table_postgres scheduled__2023-11-29T00:00:00+00:00 [queued]>
[2023-11-30T02:00:14.001+0200] {taskinstance.py:1361} INFO - Starting attempt 1 of 1
[2023-11-30T02:00:14.013+0200] {taskinstance.py:1382} INFO - Executing <Task(PostgresOperator): create_table_postgres> on 2023-11-29 00:00:00+00:00
[2023-11-30T02:00:14.016+0200] {standard_task_runner.py:57} INFO - Started process 152202 to run task
[2023-11-30T02:00:14.018+0200] {standard_task_runner.py:84} INFO - Running: ['airflow', 'tasks', 'run', 'lviv_weather', 'create_table_postgres', 'scheduled__2023-11-29T00:00:00+00:00', '--job-id', '53', '--raw', '--subdir', 'DAGS_FOLDER/lviv_weather.py', '--cfg-path', '/tmp/tmpwtwqmg0b']
[2023-11-30T02:00:14.020+0200] {standard_task_runner.py:85} INFO - Job 53: Subtask create_table_postgres
[2023-11-30T02:00:14.077+0200] {task_command.py:416} INFO - Running <TaskInstance: lviv_weather.create_table_postgres scheduled__2023-11-29T00:00:00+00:00 [running]> on host yurabd.
[2023-11-30T02:00:14.296+0200] {taskinstance.py:1662} INFO - Exporting env vars: AIRFLOW_CTX_DAG_OWNER='airflow' AIRFLOW_CTX_DAG_ID='lviv_weather' AIRFLOW_CTX_TASK_ID='create_table_postgres' AIRFLOW_CTX_EXECUTION_DATE='2023-11-29T00:00:00+00:00' AIRFLOW_CTX_TRY_NUMBER='1' AIRFLOW_CTX_DAG_RUN_ID='scheduled__2023-11-29T00:00:00+00:00'
[2023-11-30T02:00:14.297+0200] {sql.py:274} INFO - Executing: 
        CREATE TABLE IF NOT EXISTS measures
        (
        timestamp TIMESTAMP,
        date TEXT,
        temp FLOAT,
        humidity FLOAT,
        clouds FLOAT,
        wind_speed FLOAT
        );
[2023-11-30T02:00:14.320+0200] {taskinstance.py:1937} ERROR - Task failed with exception
Traceback (most recent call last):
  File "/mnt/f/UCU/BatchProc/lab1/venv/lib/python3.10/site-packages/airflow/providers/common/sql/operators/sql.py", line 275, in execute
    hook = self.get_db_hook()
  File "/mnt/f/UCU/BatchProc/lab1/venv/lib/python3.10/site-packages/airflow/providers/common/sql/operators/sql.py", line 186, in get_db_hook
    return self._hook
  File "/usr/lib/python3.10/functools.py", line 981, in __get__
    val = self.func(instance)
  File "/mnt/f/UCU/BatchProc/lab1/venv/lib/python3.10/site-packages/airflow/providers/common/sql/operators/sql.py", line 148, in _hook
    conn = BaseHook.get_connection(conn_id)
  File "/mnt/f/UCU/BatchProc/lab1/venv/lib/python3.10/site-packages/airflow/hooks/base.py", line 72, in get_connection
    conn = Connection.get_connection_from_secrets(conn_id)
  File "/mnt/f/UCU/BatchProc/lab1/venv/lib/python3.10/site-packages/airflow/models/connection.py", line 477, in get_connection_from_secrets
    raise AirflowNotFoundException(f"The conn_id `{conn_id}` isn't defined")
airflow.exceptions.AirflowNotFoundException: The conn_id `postgres_con` isn't defined
[2023-11-30T02:00:14.343+0200] {taskinstance.py:1400} INFO - Marking task as FAILED. dag_id=lviv_weather, task_id=create_table_postgres, execution_date=20231129T000000, start_date=20231130T000013, end_date=20231130T000014
[2023-11-30T02:00:14.352+0200] {standard_task_runner.py:104} ERROR - Failed to execute job 53 for task create_table_postgres (The conn_id `postgres_con` isn't defined; 152202)
[2023-11-30T02:00:14.391+0200] {local_task_job_runner.py:228} INFO - Task exited with return code 1
[2023-11-30T02:00:14.415+0200] {taskinstance.py:2778} INFO - 0 downstream tasks scheduled from follow-on schedule check
