[2023-11-30T02:17:44.608+0200] {taskinstance.py:1159} INFO - Dependencies all met for dep_context=non-requeueable deps ti=<TaskInstance: lviv_weather.process_data_Kyiv manual__2023-11-30T00:17:34.945527+00:00 [queued]>
[2023-11-30T02:17:44.615+0200] {taskinstance.py:1159} INFO - Dependencies all met for dep_context=requeueable deps ti=<TaskInstance: lviv_weather.process_data_Kyiv manual__2023-11-30T00:17:34.945527+00:00 [queued]>
[2023-11-30T02:17:44.615+0200] {taskinstance.py:1361} INFO - Starting attempt 1 of 1
[2023-11-30T02:17:44.627+0200] {taskinstance.py:1382} INFO - Executing <Task(PythonOperator): process_data_Kyiv> on 2023-11-30 00:17:34.945527+00:00
[2023-11-30T02:17:44.629+0200] {standard_task_runner.py:57} INFO - Started process 156454 to run task
[2023-11-30T02:17:44.632+0200] {standard_task_runner.py:84} INFO - Running: ['airflow', 'tasks', 'run', 'lviv_weather', 'process_data_Kyiv', 'manual__2023-11-30T00:17:34.945527+00:00', '--job-id', '74', '--raw', '--subdir', 'DAGS_FOLDER/lviv_weather.py', '--cfg-path', '/tmp/tmp48s0ahgf']
[2023-11-30T02:17:44.633+0200] {standard_task_runner.py:85} INFO - Job 74: Subtask process_data_Kyiv
[2023-11-30T02:17:44.688+0200] {task_command.py:416} INFO - Running <TaskInstance: lviv_weather.process_data_Kyiv manual__2023-11-30T00:17:34.945527+00:00 [running]> on host yurabd.
[2023-11-30T02:17:44.877+0200] {taskinstance.py:1662} INFO - Exporting env vars: AIRFLOW_CTX_DAG_OWNER='airflow' AIRFLOW_CTX_DAG_ID='lviv_weather' AIRFLOW_CTX_TASK_ID='process_data_Kyiv' AIRFLOW_CTX_EXECUTION_DATE='2023-11-30T00:17:34.945527+00:00' AIRFLOW_CTX_TRY_NUMBER='1' AIRFLOW_CTX_DAG_RUN_ID='manual__2023-11-30T00:17:34.945527+00:00'
[2023-11-30T02:17:44.891+0200] {taskinstance.py:1937} ERROR - Task failed with exception
Traceback (most recent call last):
  File "/mnt/f/UCU/BatchProc/lab1/venv/lib/python3.10/site-packages/airflow/operators/python.py", line 192, in execute
    return_value = self.execute_callable()
  File "/mnt/f/UCU/BatchProc/lab1/venv/lib/python3.10/site-packages/airflow/operators/python.py", line 209, in execute_callable
    return self.python_callable(*self.op_args, **self.op_kwargs)
  File "/home/yurabd/airflow/dags/lviv_weather.py", line 16, in _process_weather
    timestamp = info["data"][0]["dt"]
TypeError: 'NoneType' object is not subscriptable
[2023-11-30T02:17:44.909+0200] {taskinstance.py:1400} INFO - Marking task as FAILED. dag_id=lviv_weather, task_id=process_data_Kyiv, execution_date=20231130T001734, start_date=20231130T001744, end_date=20231130T001744
[2023-11-30T02:17:44.918+0200] {standard_task_runner.py:104} ERROR - Failed to execute job 74 for task process_data_Kyiv ('NoneType' object is not subscriptable; 156454)
[2023-11-30T02:17:44.925+0200] {local_task_job_runner.py:228} INFO - Task exited with return code 1
[2023-11-30T02:17:44.947+0200] {taskinstance.py:2778} INFO - 0 downstream tasks scheduled from follow-on schedule check
