[2023-11-29T17:48:01.514+0200] {taskinstance.py:1159} INFO - Dependencies all met for dep_context=non-requeueable deps ti=<TaskInstance: lviv_weather.process_data manual__2023-11-29T15:46:45.159318+00:00 [queued]>
[2023-11-29T17:48:01.522+0200] {taskinstance.py:1159} INFO - Dependencies all met for dep_context=requeueable deps ti=<TaskInstance: lviv_weather.process_data manual__2023-11-29T15:46:45.159318+00:00 [queued]>
[2023-11-29T17:48:01.522+0200] {taskinstance.py:1361} INFO - Starting attempt 1 of 1
[2023-11-29T17:48:01.590+0200] {taskinstance.py:1382} INFO - Executing <Task(PythonOperator): process_data> on 2023-11-29 15:46:45.159318+00:00
[2023-11-29T17:48:01.592+0200] {standard_task_runner.py:57} INFO - Started process 45504 to run task
[2023-11-29T17:48:01.595+0200] {standard_task_runner.py:84} INFO - Running: ['airflow', 'tasks', 'run', 'lviv_weather', 'process_data', 'manual__2023-11-29T15:46:45.159318+00:00', '--job-id', '21', '--raw', '--subdir', 'DAGS_FOLDER/lviv_weather.py', '--cfg-path', '/tmp/tmpme9nwrjk']
[2023-11-29T17:48:01.595+0200] {standard_task_runner.py:85} INFO - Job 21: Subtask process_data
[2023-11-29T17:48:01.624+0200] {task_command.py:416} INFO - Running <TaskInstance: lviv_weather.process_data manual__2023-11-29T15:46:45.159318+00:00 [running]> on host yurabd.
[2023-11-29T17:48:01.672+0200] {taskinstance.py:1662} INFO - Exporting env vars: AIRFLOW_CTX_DAG_OWNER='airflow' AIRFLOW_CTX_DAG_ID='lviv_weather' AIRFLOW_CTX_TASK_ID='process_data' AIRFLOW_CTX_EXECUTION_DATE='2023-11-29T15:46:45.159318+00:00' AIRFLOW_CTX_TRY_NUMBER='1' AIRFLOW_CTX_DAG_RUN_ID='manual__2023-11-29T15:46:45.159318+00:00'
[2023-11-29T17:48:01.676+0200] {taskinstance.py:1937} ERROR - Task failed with exception
Traceback (most recent call last):
  File "/mnt/f/UCU/BatchProc/lab1/venv/lib/python3.10/site-packages/airflow/operators/python.py", line 192, in execute
    return_value = self.execute_callable()
  File "/mnt/f/UCU/BatchProc/lab1/venv/lib/python3.10/site-packages/airflow/operators/python.py", line 209, in execute_callable
    return self.python_callable(*self.op_args, **self.op_kwargs)
  File "/home/yurabd/airflow/dags/lviv_weather.py", line 10, in _process_weather
    timestamp = info["dt"]
TypeError: 'NoneType' object is not subscriptable
[2023-11-29T17:48:01.683+0200] {taskinstance.py:1400} INFO - Marking task as FAILED. dag_id=lviv_weather, task_id=process_data, execution_date=20231129T154645, start_date=20231129T154801, end_date=20231129T154801
[2023-11-29T17:48:01.695+0200] {standard_task_runner.py:104} ERROR - Failed to execute job 21 for task process_data ('NoneType' object is not subscriptable; 45504)
[2023-11-29T17:48:01.727+0200] {local_task_job_runner.py:228} INFO - Task exited with return code 1
[2023-11-29T17:48:01.742+0200] {taskinstance.py:2778} INFO - 0 downstream tasks scheduled from follow-on schedule check
