[2023-11-29T18:40:00.525+0200] {taskinstance.py:1159} INFO - Dependencies all met for dep_context=non-requeueable deps ti=<TaskInstance: lviv_weather.check_api manual__2023-11-29T16:39:15.949409+00:00 [queued]>
[2023-11-29T18:40:00.532+0200] {taskinstance.py:1159} INFO - Dependencies all met for dep_context=requeueable deps ti=<TaskInstance: lviv_weather.check_api manual__2023-11-29T16:39:15.949409+00:00 [queued]>
[2023-11-29T18:40:00.532+0200] {taskinstance.py:1361} INFO - Starting attempt 1 of 1
[2023-11-29T18:40:00.598+0200] {taskinstance.py:1382} INFO - Executing <Task(HttpSensor): check_api> on 2023-11-29 16:39:15.949409+00:00
[2023-11-29T18:40:00.601+0200] {standard_task_runner.py:57} INFO - Started process 57881 to run task
[2023-11-29T18:40:00.603+0200] {standard_task_runner.py:84} INFO - Running: ['airflow', 'tasks', 'run', 'lviv_weather', 'check_api', 'manual__2023-11-29T16:39:15.949409+00:00', '--job-id', '28', '--raw', '--subdir', 'DAGS_FOLDER/lviv_weather.py', '--cfg-path', '/tmp/tmp44gf62xs']
[2023-11-29T18:40:00.603+0200] {standard_task_runner.py:85} INFO - Job 28: Subtask check_api
[2023-11-29T18:40:00.631+0200] {task_command.py:416} INFO - Running <TaskInstance: lviv_weather.check_api manual__2023-11-29T16:39:15.949409+00:00 [running]> on host yurabd.
[2023-11-29T18:40:00.680+0200] {taskinstance.py:1662} INFO - Exporting env vars: AIRFLOW_CTX_DAG_OWNER='airflow' AIRFLOW_CTX_DAG_ID='lviv_weather' AIRFLOW_CTX_TASK_ID='check_api' AIRFLOW_CTX_EXECUTION_DATE='2023-11-29T16:39:15.949409+00:00' AIRFLOW_CTX_TRY_NUMBER='1' AIRFLOW_CTX_DAG_RUN_ID='manual__2023-11-29T16:39:15.949409+00:00'
[2023-11-29T18:40:00.680+0200] {http.py:130} INFO - Poking: data/3.0/weather
[2023-11-29T18:40:00.683+0200] {base.py:73} INFO - Using connection ID 'weather_conn' for task execution.
[2023-11-29T18:40:00.919+0200] {http.py:178} ERROR - HTTP error: Not Found
[2023-11-29T18:40:00.919+0200] {http.py:179} ERROR - {"cod":"404","message":"Internal error"}
[2023-11-29T18:41:00.926+0200] {http.py:130} INFO - Poking: data/3.0/weather
[2023-11-29T18:41:00.929+0200] {base.py:73} INFO - Using connection ID 'weather_conn' for task execution.
[2023-11-29T18:41:01.163+0200] {http.py:178} ERROR - HTTP error: Not Found
[2023-11-29T18:41:01.163+0200] {http.py:179} ERROR - {"cod":"404","message":"Internal error"}
[2023-11-29T18:42:01.216+0200] {http.py:130} INFO - Poking: data/3.0/weather
[2023-11-29T18:42:01.219+0200] {base.py:73} INFO - Using connection ID 'weather_conn' for task execution.
[2023-11-29T18:42:01.449+0200] {http.py:178} ERROR - HTTP error: Not Found
[2023-11-29T18:42:01.449+0200] {http.py:179} ERROR - {"cod":"404","message":"Internal error"}
[2023-11-29T18:43:01.467+0200] {http.py:130} INFO - Poking: data/3.0/weather
[2023-11-29T18:43:01.469+0200] {base.py:73} INFO - Using connection ID 'weather_conn' for task execution.
[2023-11-29T18:43:01.776+0200] {http.py:178} ERROR - HTTP error: Not Found
[2023-11-29T18:43:01.776+0200] {http.py:179} ERROR - {"cod":"404","message":"Internal error"}
[2023-11-29T18:44:01.813+0200] {http.py:130} INFO - Poking: data/3.0/weather
[2023-11-29T18:44:01.816+0200] {base.py:73} INFO - Using connection ID 'weather_conn' for task execution.
[2023-11-29T18:44:02.051+0200] {http.py:178} ERROR - HTTP error: Not Found
[2023-11-29T18:44:02.051+0200] {http.py:179} ERROR - {"cod":"404","message":"Internal error"}
[2023-11-29T18:45:02.112+0200] {http.py:130} INFO - Poking: data/3.0/weather
[2023-11-29T18:45:02.115+0200] {base.py:73} INFO - Using connection ID 'weather_conn' for task execution.
[2023-11-29T18:45:02.351+0200] {http.py:178} ERROR - HTTP error: Not Found
[2023-11-29T18:45:02.351+0200] {http.py:179} ERROR - {"cod":"404","message":"Internal error"}
[2023-11-29T18:46:02.361+0200] {http.py:130} INFO - Poking: data/3.0/weather
[2023-11-29T18:46:02.363+0200] {base.py:73} INFO - Using connection ID 'weather_conn' for task execution.
[2023-11-29T18:46:02.601+0200] {http.py:178} ERROR - HTTP error: Not Found
[2023-11-29T18:46:02.601+0200] {http.py:179} ERROR - {"cod":"404","message":"Internal error"}
[2023-11-29T18:47:02.656+0200] {http.py:130} INFO - Poking: data/3.0/weather
[2023-11-29T18:47:02.659+0200] {base.py:73} INFO - Using connection ID 'weather_conn' for task execution.
[2023-11-29T18:47:02.909+0200] {http.py:178} ERROR - HTTP error: Not Found
[2023-11-29T18:47:02.909+0200] {http.py:179} ERROR - {"cod":"404","message":"Internal error"}
[2023-11-29T18:48:02.970+0200] {http.py:130} INFO - Poking: data/3.0/weather
[2023-11-29T18:48:02.973+0200] {base.py:73} INFO - Using connection ID 'weather_conn' for task execution.
[2023-11-29T18:48:03.271+0200] {http.py:178} ERROR - HTTP error: Not Found
[2023-11-29T18:48:03.272+0200] {http.py:179} ERROR - {"cod":"404","message":"Internal error"}
[2023-11-29T18:48:28.544+0200] {local_task_job_runner.py:294} WARNING - State of this instance has been externally set to failed. Terminating instance.
[2023-11-29T18:48:28.546+0200] {process_utils.py:131} INFO - Sending 15 to group 57881. PIDs of all processes in the group: [57881]
[2023-11-29T18:48:28.546+0200] {process_utils.py:86} INFO - Sending the signal 15 to group 57881
[2023-11-29T18:48:28.546+0200] {taskinstance.py:1632} ERROR - Received SIGTERM. Terminating subprocesses.
[2023-11-29T18:48:28.573+0200] {process_utils.py:79} INFO - Process psutil.Process(pid=57881, status='terminated', exitcode=0, started='18:40:00') (57881) terminated with exit code 0
