[2023-11-30T03:08:13.000+0200] {taskinstance.py:1159} INFO - Dependencies all met for dep_context=non-requeueable deps ti=<TaskInstance: lviv_weather.inject_data_Kyiv manual__2023-11-30T01:08:02.988304+00:00 [queued]>
[2023-11-30T03:08:13.008+0200] {taskinstance.py:1159} INFO - Dependencies all met for dep_context=requeueable deps ti=<TaskInstance: lviv_weather.inject_data_Kyiv manual__2023-11-30T01:08:02.988304+00:00 [queued]>
[2023-11-30T03:08:13.008+0200] {taskinstance.py:1361} INFO - Starting attempt 1 of 1
[2023-11-30T03:08:13.021+0200] {taskinstance.py:1382} INFO - Executing <Task(PostgresOperator): inject_data_Kyiv> on 2023-11-30 01:08:02.988304+00:00
[2023-11-30T03:08:13.024+0200] {standard_task_runner.py:57} INFO - Started process 169108 to run task
[2023-11-30T03:08:13.027+0200] {standard_task_runner.py:84} INFO - Running: ['airflow', 'tasks', 'run', 'lviv_weather', 'inject_data_Kyiv', 'manual__2023-11-30T01:08:02.988304+00:00', '--job-id', '186', '--raw', '--subdir', 'DAGS_FOLDER/lviv_weather.py', '--cfg-path', '/tmp/tmplq69dzam']
[2023-11-30T03:08:13.029+0200] {standard_task_runner.py:85} INFO - Job 186: Subtask inject_data_Kyiv
[2023-11-30T03:08:13.089+0200] {task_command.py:416} INFO - Running <TaskInstance: lviv_weather.inject_data_Kyiv manual__2023-11-30T01:08:02.988304+00:00 [running]> on host yurabd.
[2023-11-30T03:08:13.239+0200] {abstractoperator.py:709} ERROR - Exception rendering Jinja template for task 'inject_data_Kyiv', field 'sql'. Template: "\n            INSERT INTO measures (city, timestamp, date, temp, humidity, clouds, wind_speed) VALUES\n            ('{{ params.city }}',\n            to_timestamp({{ti.xcom_pull(task_ids='process_data_' + params.city)[1]}}),\n            '{{ti.xcom_pull(task_ids='process_data_' + params.city)[2]}}',\n            {{ti.xcom_pull(task_ids='process_data_' + params.city)[3]}},\n            {{ti.xcom_pull(task_ids='process_data_' + params.city)[4]}},\n            {{ti.xcom_pull(task_ids='process_data_' + params.city)[5]}},\n            {{ti.xcom_pull(task_ids='process_data_' + params.city)[6]}});\n            "
Traceback (most recent call last):
  File "/mnt/f/UCU/BatchProc/lab1/venv/lib/python3.10/site-packages/airflow/models/abstractoperator.py", line 701, in _do_render_template_fields
    rendered_content = self.render_template(
  File "/mnt/f/UCU/BatchProc/lab1/venv/lib/python3.10/site-packages/airflow/template/templater.py", line 155, in render_template
    return self._render(template, context)
  File "/mnt/f/UCU/BatchProc/lab1/venv/lib/python3.10/site-packages/airflow/models/abstractoperator.py", line 655, in _render
    return super()._render(template, context, dag=dag)
  File "/mnt/f/UCU/BatchProc/lab1/venv/lib/python3.10/site-packages/airflow/template/templater.py", line 112, in _render
    return render_template_to_string(template, context)
  File "/mnt/f/UCU/BatchProc/lab1/venv/lib/python3.10/site-packages/airflow/utils/helpers.py", line 289, in render_template_to_string
    return render_template(template, cast(MutableMapping[str, Any], context), native=False)
  File "/mnt/f/UCU/BatchProc/lab1/venv/lib/python3.10/site-packages/airflow/utils/helpers.py", line 284, in render_template
    return "".join(nodes)
  File "<template>", line 26, in root
  File "/mnt/f/UCU/BatchProc/lab1/venv/lib/python3.10/site-packages/jinja2/runtime.py", line 852, in _fail_with_undefined_error
    raise self._undefined_exception(self._undefined_message)
jinja2.exceptions.UndefinedError: tuple object has no element 6
[2023-11-30T03:08:13.252+0200] {taskinstance.py:1937} ERROR - Task failed with exception
Traceback (most recent call last):
  File "/mnt/f/UCU/BatchProc/lab1/venv/lib/python3.10/site-packages/airflow/models/taskinstance.py", line 1518, in _run_raw_task
    self._execute_task_with_callbacks(context, test_mode, session=session)
  File "/mnt/f/UCU/BatchProc/lab1/venv/lib/python3.10/site-packages/airflow/models/taskinstance.py", line 1647, in _execute_task_with_callbacks
    task_orig = self.render_templates(context=context)
  File "/mnt/f/UCU/BatchProc/lab1/venv/lib/python3.10/site-packages/airflow/models/taskinstance.py", line 2285, in render_templates
    original_task.render_template_fields(context)
  File "/mnt/f/UCU/BatchProc/lab1/venv/lib/python3.10/site-packages/airflow/models/baseoperator.py", line 1243, in render_template_fields
    self._do_render_template_fields(self, self.template_fields, context, jinja_env, set())
  File "/mnt/f/UCU/BatchProc/lab1/venv/lib/python3.10/site-packages/airflow/utils/session.py", line 79, in wrapper
    return func(*args, session=session, **kwargs)
  File "/mnt/f/UCU/BatchProc/lab1/venv/lib/python3.10/site-packages/airflow/models/abstractoperator.py", line 701, in _do_render_template_fields
    rendered_content = self.render_template(
  File "/mnt/f/UCU/BatchProc/lab1/venv/lib/python3.10/site-packages/airflow/template/templater.py", line 155, in render_template
    return self._render(template, context)
  File "/mnt/f/UCU/BatchProc/lab1/venv/lib/python3.10/site-packages/airflow/models/abstractoperator.py", line 655, in _render
    return super()._render(template, context, dag=dag)
  File "/mnt/f/UCU/BatchProc/lab1/venv/lib/python3.10/site-packages/airflow/template/templater.py", line 112, in _render
    return render_template_to_string(template, context)
  File "/mnt/f/UCU/BatchProc/lab1/venv/lib/python3.10/site-packages/airflow/utils/helpers.py", line 289, in render_template_to_string
    return render_template(template, cast(MutableMapping[str, Any], context), native=False)
  File "/mnt/f/UCU/BatchProc/lab1/venv/lib/python3.10/site-packages/airflow/utils/helpers.py", line 284, in render_template
    return "".join(nodes)
  File "<template>", line 26, in root
  File "/mnt/f/UCU/BatchProc/lab1/venv/lib/python3.10/site-packages/jinja2/runtime.py", line 852, in _fail_with_undefined_error
    raise self._undefined_exception(self._undefined_message)
jinja2.exceptions.UndefinedError: tuple object has no element 6
[2023-11-30T03:08:13.385+0200] {taskinstance.py:1400} INFO - Marking task as FAILED. dag_id=lviv_weather, task_id=inject_data_Kyiv, execution_date=20231130T010802, start_date=20231130T010813, end_date=20231130T010813
[2023-11-30T03:08:13.396+0200] {standard_task_runner.py:104} ERROR - Failed to execute job 186 for task inject_data_Kyiv (tuple object has no element 6; 169108)
[2023-11-30T03:08:13.440+0200] {local_task_job_runner.py:228} INFO - Task exited with return code 1
[2023-11-30T03:08:13.466+0200] {taskinstance.py:2778} INFO - 0 downstream tasks scheduled from follow-on schedule check
